<?xml version='1.0'?>

<robot name="myrobot" xmlns:xacro="http://www.ros.org/wiki/xacro">

  <xacro:property name="cameraSize" value="0.05"/>
  <xacro:property name="cameraMass" value="0.1"/>
  <xacro:property name="camera_link" value="0.05" /> 

  <xacro:include filename="$(find mybot_description)/urdf/mybot.gazebo" />
  <xacro:include filename="$(find mybot_description)/urdf/materials.xacro" />
  <xacro:include filename="$(find mybot_description)/urdf/macros.xacro" />


  <link name='chassis'>
    <pose>0 0 0.1 0 0 0</pose>

    <inertial>
      <mass value="5.0"/>
      <origin xyz="0.0 0 0.1" rpy=" 0 0 0"/>
      <inertia
          ixx="0.1" ixy="0" ixz="0"
          iyy="0.1" iyz="0"
          izz="0.1"
      />
    </inertial>

    <collision name='collision'>
      <geometry>
        <box size=".38 .2 .13"/>
      </geometry>
    </collision>

    <visual name='chassis_visual'>
      <origin xyz="0 0 0" rpy=" 0 0 0"/>
      <geometry>
        <box size=".38 .2 .13"/>
      </geometry>
    </visual>
</link>




  <link name="left_back_wheel">
    <!--origin xyz="0.1 0.13 0.1" rpy="0 1.5707 1.5707"/-->
    <collision name="collision">
      <origin xyz="0 0 0" rpy="0 1.5707 1.5707"/>
      <geometry>
        <cylinder radius="0.08" length="0.05"/>
      </geometry>
      
   
    </collision>
    <visual name="left_back_wheel_visual">
      <origin xyz="0 0 0" rpy="0 1.5707 1.5707"/>
      <geometry>
        <cylinder radius="0.08" length="0.05"/>
      </geometry>
    </visual>
    <inertial>
      <origin xyz="0 0 0" rpy="0 1.5707 1.5707"/>
      <mass value="5"/>
      <inertia
        ixx=".1" ixy="0.0" ixz="0.0"
        iyy=".1" iyz="0.0"
        izz=".1"/>
    </inertial>
  </link>

  <link name="right_back_wheel">
    <!--origin xyz="0.1 -0.13 0.1" rpy="0 1.5707 1.5707"/-->
    <collision name="collision">
      <origin xyz="0 0 0" rpy="0 1.5707 1.5707"/>
      <geometry>
        <cylinder radius="0.08" length="0.05"/>
      </geometry>
     
      
    </collision>
    <visual name="right_back_wheel_visual">
      <origin xyz="0 0 0" rpy="0 1.5707 1.5707"/>
      <geometry>
        <cylinder radius="0.08" length="0.05"/>
      </geometry>
    </visual>
    <inertial>
      <origin xyz="0 0 0" rpy="0 1.5707 1.5707"/>
      <mass value="5"/>
      <inertia
        ixx=".1" ixy="0.0" ixz="0.0"
        iyy=".1" iyz="0.0"
        izz=".1"/>
    </inertial>
  </link>

  <link name="left_front_wheel">
    <!--origin xyz="0.1 0.13 0.1" rpy="0 1.5707 1.5707"/-->
    <collision name="collision">
      <origin xyz="0 0 0" rpy="0 1.5707 1.5707"/>
      <geometry>
        <cylinder radius="0.08" length="0.05"/>
      </geometry>
      
    
    </collision>
    <visual name="left_front_wheel_visual">
      <origin xyz="0 0 0" rpy="0 1.5707 1.5707"/>
      <geometry>
        <cylinder radius="0.08" length="0.05"/>
      </geometry>
    </visual>
    <inertial>
      <origin xyz="0 0 0" rpy="0 1.5707 1.5707"/>
      <mass value="5"/>
      <inertia
        ixx=".1" ixy="0.0" ixz="0.0"
        iyy=".1" iyz="0.0"
        izz=".1"/>
    </inertial>
  </link>

  <link name="right_front_wheel">
    <!--origin xyz="0.1 -0.13 0.1" rpy="0 1.5707 1.5707"/-->
    <collision name="collision">
      <origin xyz="0 0 0" rpy="0 1.5707 1.5707"/>
      <geometry>
        <cylinder radius="0.08" length="0.05"/>
      </geometry>

    
    </collision>
    <visual name="right_front_wheel_visual">
      <origin xyz="0 0 0" rpy="0 1.5707 1.5707"/>
      <geometry>
        <cylinder radius="0.08" length="0.05"/>
      </geometry>
    </visual>
    <inertial>
      <origin xyz="0 0 0" rpy="0 1.5707 1.5707"/>
      <mass value="5"/>
      <inertia
        ixx=".1" ixy="0.0" ixz="0.0"
        iyy=".1" iyz="0.0"
        izz=".1"/>
    </inertial>
  </link>

  <joint type="continuous" name="left_back_wheel_hinge">
    <origin xyz="-0.1 0.15 0" rpy="0 0 0"/>
    <!--origin xyz="0.1 0.13 0" rpy="0 1.5707 1.5707"/-->
    <child link="left_back_wheel"/>
    <parent link="chassis"/>
    <axis xyz="0 1 0" rpy="0 0 0"/>
    <limit effort="10000" velocity="1000"/>
    
  </joint>

  <joint type="continuous" name="right_back_wheel_hinge">
    <origin xyz="-0.1 -0.15 0" rpy="0 0 0"/>
    <!--origin xyz="0.1 -0.13 0" rpy="0 1.5707 1.5707"/-->
    <child link="right_back_wheel"/>
    <parent link="chassis"/>
    <axis xyz="0 1 0" rpy="0 0 0"/>
    <limit effort="10000" velocity="1000"/>
    
  </joint>

 <joint type="continuous" name="left_front_wheel_hinge">
    <origin xyz="0.1 0.15 0" rpy="0 0 0"/>
    <!--origin xyz="0.1 0.13 0" rpy="0 1.5707 1.5707"/-->
    <child link="left_front_wheel"/>
    <parent link="chassis"/>
    <axis xyz="0 1 0" rpy="0 0 0"/>
    <limit effort="10000" velocity="1000"/>
    
  </joint>

  <joint type="continuous" name="right_front_wheel_hinge">
    <origin xyz="0.1 -0.15 0" rpy="0 0 0"/>
    <!--origin xyz="0.1 -0.13 0" rpy="0 1.5707 1.5707"/-->
    <child link="right_front_wheel"/>
    <parent link="chassis"/>
    <axis xyz="0 1 0" rpy="0 0 0"/>
    <limit effort="10000" velocity="1000"/>
    
  </joint>


<transmission name="$left_front_trans">
  <type>transmission_interface/SimpleTransmission</type>
  <joint name="$left_front_wheel_hinge">
  <hardwareInterface>hardwareInterface>EffortJointInterface</hardwareInterface>
  </joint>
  <actuator name="$left_front_Motor">
    <hardwareInterface>EffortJointInterface</hardwareInterface>
    <mechanicalReduction>10</mechanicalReduction>
  </actuator>
</transmission>

<transmission name="$left_back_trans">
  <type>transmission_interface/SimpleTransmission</type>
  <joint name="$left_back_wheel_hinge">
  <hardwareInterface>hardwareInterface>EffortJointInterface</hardwareInterface>
  </joint>
  <actuator name="$left_back_Motor">
    <hardwareInterface>EffortJointInterface</hardwareInterface>
    <mechanicalReduction>10</mechanicalReduction>
  </actuator>
</transmission>

<transmission name="$right_back_trans">
  <type>transmission_interface/SimpleTransmission</type>
  <joint name="$right_back_wheel_hinge">
  <hardwareInterface>hardwareInterface>EffortJointInterface</hardwareInterface>  
  </joint>
  <actuator name="$right_back_Motor">
    <hardwareInterface>EffortJointInterface</hardwareInterface>
    <mechanicalReduction>10</mechanicalReduction>
  </actuator>
</transmission>

<transmission name="$right_front_trans">
  <type>transmission_interface/SimpleTransmission</type>
  <joint name="$right_front_wheel_hinge">
  <hardwareInterface>hardwareInterface>EffortJointInterface</hardwareInterface>
  </joint>
  <actuator name="$right_front_Motor">
    <hardwareInterface>EffortJointInterface</hardwareInterface>
    <mechanicalReduction>10</mechanicalReduction>
  </actuator>
</transmission>




 
</robot>

